Workbook
Name Elements: 'Lookup-General'!$AA$1
Name lstAoI: 'Lookup-Influence'!$A$2:$A$17
Name lstBanes: Lists!$I$1:$I$20
Name lstBenefactor: Lists!$O$2:$O$15
Name lstBloodlines: Lists!$E$1:$E$106
Name lstCarthianLaw: Lists!$L$1:$L$14
Name lstClan: Lists!$D$1:$D$6
Name lstCovenant: Lists!$F$1:$F$6
Name lstDevotions: Lists!$K$2:$K$58
Name lstDisciplines: Lists!$G$1:$G$11
Name lstInvictusOaths: Lists!$M$1:$M$16
Name lstManoeuvres: tblManoeuvre[Manoeuvre]
Name lstManoeuvres: tblManoeuvre[Manoeuvre]
Name lstManoeuvres: tblManoeuvre[Manoeuvre]
Name lstManoeuvres: tblManoeuvre[Manoeuvre]
Name lstManoeuvres: tblManoeuvre[Manoeuvre]
Name lstManoeuvres: tblManoeuvre[Manoeuvre]
Name lstManoeuvres: tblManoeuvre[Manoeuvre]
Name lstManoeuvres: tblManoeuvre[Manoeuvre]
Name lstManoeuvres: tblManoeuvre[Manoeuvre]
Name lstManoeuvres: tblManoeuvre[Manoeuvre]
Name lstManoeuvres: tblManoeuvre[Manoeuvre]
Name lstManoeuvres: tblManoeuvre[Manoeuvre]
Name lstManoeuvres: tblManoeuvre[Manoeuvre]
Name lstManoeuvres: tblManoeuvre[Manoeuvre]
Name lstManoeuvres: tblManoeuvre[Manoeuvre]
Name lstManoeuvres: tblManoeuvre[Manoeuvre]
Name lstManoeuvres: tblManoeuvre[Manoeuvre]
Name lstManoeuvres: tblManoeuvre[Manoeuvre]
Name lstManoeuvres: tblManoeuvre[Manoeuvre]
Name lstManoeuvres: tblManoeuvre[Manoeuvre]
Name lstManoeuvres: tblManoeuvre[Manoeuvre]
Name lstManoeuvres: tblManoeuvre[Manoeuvre]
Name lstManoeuvres: tblManoeuvre[Manoeuvre]
Name lstManoeuvres: tblManoeuvre[Manoeuvre]
Name lstManoeuvres: tblManoeuvre[Manoeuvre]
Name lstManoeuvres: tblManoeuvre[Manoeuvre]
Name lstManoeuvres: tblManoeuvre[Manoeuvre]
Name lstManoeuvres: tblManoeuvre[Manoeuvre]
Name lstManoeuvres: tblManoeuvre[Manoeuvre]
Name lstManoeuvres: tblManoeuvre[Manoeuvre]
Name lstManoeuvres: tblManoeuvre[Manoeuvre]
Name lstManoeuvres: tblManoeuvre[Manoeuvre]
Name lstMerits: tblMerits[Merit]
Name lstMerits: tblMerits[Merit]
Name lstMerits: tblMerits[Merit]
Name lstMerits: tblMerits[Merit]
Name lstMerits: tblMerits[Merit]
Name lstMerits: tblMerits[Merit]
Name lstMerits: tblMerits[Merit]
Name lstMerits: tblMerits[Merit]
Name lstMerits: tblMerits[Merit]
Name lstMerits: tblMerits[Merit]
Name lstMerits: tblMerits[Merit]
Name lstMerits: tblMerits[Merit]
Name lstMerits: tblMerits[Merit]
Name lstMerits: tblMerits[Merit]
Name lstMerits: tblMerits[Merit]
Name lstMerits: tblMerits[Merit]
Name lstMerits: tblMerits[Merit]

Sheet Character Data
A1: Sheet | B1: Date | C1: XP Left | D1: XP Total | E1: Player Name | F1: Character Name | G1: Concept | H1: Pronouns | I1: Clan | J1: Clan Icon | K1: Bloodline | L1: Covenant | M1: Covenant Icon | N1: Mask | O1: Dirge | P1: Court Title | Q1: Intelligence | R1: Wits | S1: Resolve | T1: Strength | U1: Dexterity | V1: Stamina | W1: Presence | X1: Manipulation | Y1: Composure | Z1: Academics | AA1: Computer | AB1: Crafts | AC1: Investigation | AD1: Medicine | AE1: Occult | AF1: Politics | AG1: Science | AH1: Athletics | AI1: Brawl | AJ1: Drive | AK1: Firearms | AL1: Larceny | AM1: Stealth | AN1: Survival | AO1: Weaponry | AP1: Animal Ken | AQ1: Empathy | AR1: Expression | AS1: Intimidation | AT1: Persuasion | AU1: Socialise | AV1: Streetwise | AW1: Subterfuge | AX1: Blood Potency | AY1: BP | AZ1: BP Icon | BA1: Health | BB1: Willpower | BC1: Willpower Squares | BD1: Vitae | BE1: Vitae Squares | BF1: Vitae Per Turn | BG1: Can Feed From | BH1: Academics Spec | BI1: Computer Spec | BJ1: Crafts Spec | BK1: Investigation Spec | BL1: Medicine Spec | BM1: Occult Spec | BN1: Politics Spec | BO1: Science Spec | BP1: Athletics Spec | BQ1: Brawl Spec | BR1: Drive Spec | BS1: Firearms Spec | BT1: Larceny Spec | BU1: Stealth Spec | BV1: Survival Spec | BW1: Weaponry Spec | BX1: Animal Ken Spec | BY1: Empathy Spec | BZ1: Expression Spec | CA1: Intimidation Spec | CB1: Persuasion Spec | CC1: Socialise Spec | CD1: Streetwise Spec | CE1: Subterfuge Spec | CF1: City Status | CG1: Clan Status | CH1: Covenant Status | CI1: Covenant 1 | CJ1: Covenant Status 1 | CK1: Covenant 2 | CL1: Covenant Status 2 | CM1: Covenant 3 | CN1: Covenant Status 3 | CO1: Covenant 4 | CP1: Covenant Status 4 | CQ1: Safe Place | CR1: Haven | CS1: Feeding Grounds | CT1: Herd | CU1: Mystery Cult Initiation | CV1: Mystery Cult Name | CW1: Professional Training | CX1: Prof Training Role | CY1: Hum | CZ1: Hum Icon | DA1: Humanity 10 | DB1: Humanity 9 | DC1: Humanity 8 | DD1: Humanity 7 | DE1: Humanity 6 | DF1: Humanity 5 | DG1: Humanity 4 | DH1: Humanity 3 | DI1: Humanity 2 | DJ1: Humanity 1 | DK1: Merit 1 | DL1: Merit 2 | DM1: Merit 3 | DN1: Merit 4 | DO1: Merit 5 | DP1: Merit 6 | DQ1: Merit 7 | DR1: Merit 8 | DS1: Merit 9 | DT1: Merit 10 | DU1: Merit 11 | DV1: Merit 12 | DW1: Merit 13 | DX1: Merit 14 | DY1: Merit 15 | DZ1: Merit 16 | EA1: Merit 17 | EB1: Merit 18 | EC1: Merit 19 | ED1: Merit 20 | EE1: Merit 21 | EF1: Merit 22 | EG1: Merit 23 | EH1: Merit 24 | EI1: Merit 25 | EJ1: Merit 26 | EK1: Merit 27 | EL1: Merit 28 | EM1: Merit 29 | EN1: Merit 30 | EO1: Merit Effect 1 | EP1: Merit Effect 2 | EQ1: Merit Effect 3 | ER1: Merit Effect 4 | ES1: Merit Effect 5 | ET1: Merit Effect 6 | EU1: Merit Effect 7 | EV1: Merit Effect 8 | EW1: Merit Effect 9 | EX1: Merit Effect 10 | EY1: Merit Effect 11 | EZ1: Merit Effect 12 | FA1: Merit Effect 13 | FB1: Merit Effect 14 | FC1: Merit Effect 15 | FD1: Merit Effect 16 | FE1: Merit Effect 17 | FF1: Merit Effect 18 | FG1: Merit Effect 19 | FH1: Merit Effect 20 | FI1: Merit Effect 21 | FJ1: Merit Effect 22 | FK1: Merit Effect 23 | FL1: Merit Effect 24 | FM1: Merit Effect 25 | FN1: Merit Effect 26 | FO1: Merit Effect 27 | FP1: Merit Effect 28 | FQ1: Merit Effect 29 | FR1: Merit Effect 30 | FS1: Influence | FT1: Influence Squares | FU1: Influence 1 | FV1: Influence 2 | FW1: Influence 3 | FX1: Influence 4 | FY1: Influence 5 | FZ1: Influence 6 | GA1: Influence 7 | GB1: Influence 8 | GC1: Influence 9 | GD1: Influence 10 | GE1: Influence 11 | GF1: Influence 12 | GG1: Influence 13 | GH1: Influence 14 | GI1: Influence 15 | GJ1: Influence 16 | GK1: Influence 17 | GL1: Influence 18 | GM1: Influence 19 | GN1: Influence 20 | GO1: Area 1 | GP1: Area 2 | GQ1: Area 3 | GR1: Area 4 | GS1: Area 5 | GT1: Area 6 | GU1: Area 7 | GV1: Area 8 | GW1: Area 9 | GX1: Area 10 | GY1: Area 11 | GZ1: Area 12 | HA1: Area 13 | HB1: Area 14 | HC1: Area 15 | HD1: Area 16 | HE1: Area 17 | HF1: Area 18 | HG1: Area 19 | HH1: Area 20 | HI1: Influence Dots 1 | HJ1: Influence Dots 2 | HK1: Influence Dots 3 | HL1: Influence Dots 4 | HM1: Influence Dots 5 | HN1: Influence Dots 6 | HO1: Influence Dots 7 | HP1: Influence Dots 8 | HQ1: Influence Dots 9 | HR1: Influence Dots 10 | HS1: Influence Dots 11 | HT1: Influence Dots 12 | HU1: Influence Dots 13 | HV1: Influence Dots 14 | HW1: Influence Dots 15 | HX1: Influence Dots 16 | HY1: Influence Dots 17 | HZ1: Influence Dots 18 | IA1: Influence Dots 19 | IB1: Influence Dots 20 | IC1: Animalism | ID1: Auspex | IE1: Celerity | IF1: Dominate | IG1: Majesty | IH1: Nightmare | II1: Obfuscate | IJ1: Protean | IK1: Resilience | IL1: Vigour | IM1: Cruac | IN1: Theban | IO1: Creation | IP1: Destruction | IQ1: Divination | IR1: Protection | IS1: Transmutation | IT1: Blood 1 | IU1: Blood 2 | IV1: Blood 3 | IW1: Blood 4 | IX1: Blood 5 | IY1: Blood 6 | IZ1: Blood 7 | JA1: Blood 8 | JB1: Blood 9 | JC1: Blood 10 | JD1: Blood 11 | JE1: Blood 12 | JF1: Blood 13 | JG1: Blood 14 | JH1: Blood 15 | JI1: Blood 16 | JJ1: Blood 17 | JK1: Blood 18 | JL1: Blood 19 | JM1: Blood 20 | JN1: Blood 21 | JO1: Blood 22 | JP1: Blood 23 | JQ1: Blood 24 | JR1: Blood 25 | JS1: Blood 26 | JT1: Blood 27 | JU1: Blood 28 | JV1: Blood 29 | JW1: Blood 30 | JX1: Blood Stats 1 | JY1: Blood Stats 2 | JZ1: Blood Stats 3 | KA1: Blood Stats 4 | KB1: Blood Stats 5 | KC1: Blood Stats 6 | KD1: Blood Stats 7 | KE1: Blood Stats 8 | KF1: Blood Stats 9 | KG1: Blood Stats 10 | KH1: Blood Stats 11 | KI1: Blood Stats 12 | KJ1: Blood Stats 13 | KK1: Blood Stats 14 | KL1: Blood Stats 15 | KM1: Blood Stats 16 | KN1: Blood Stats 17 | KO1: Blood Stats 18 | KP1: Blood Stats 19 | KQ1: Blood Stats 20 | KR1: Blood Stats 21 | KS1: Blood Stats 22 | KT1: Blood Stats 23 | KU1: Blood Stats 24 | KV1: Blood Stats 25 | KW1: Blood Stats 26 | KX1: Blood Stats 27 | KY1: Blood Stats 28 | KZ1: Blood Stats 29 | LA1: Blood Stats 30 | LB1: Blood Effect 1 | LC1: Blood Effect 2 | LD1: Blood Effect 3 | LE1: Blood Effect 4 | LF1: Blood Effect 5 | LG1: Blood Effect 6 | LH1: Blood Effect 7 | LI1: Blood Effect 8 | LJ1: Blood Effect 9 | LK1: Blood Effect 10 | LL1: Blood Effect 11 | LM1: Blood Effect 12 | LN1: Blood Effect 13 | LO1: Blood Effect 14 | LP1: Blood Effect 15 | LQ1: Blood Effect 16 | LR1: Blood Effect 17 | LS1: Blood Effect 18 | LT1: Blood Effect 19 | LU1: Blood Effect 20 | LV1: Blood Effect 21 | LW1: Blood Effect 22 | LX1: Blood Effect 23 | LY1: Blood Effect 24 | LZ1: Blood Effect 25 | MA1: Blood Effect 26 | MB1: Blood Effect 27 | MC1: Blood Effect 28 | MD1: Blood Effect 29 | ME1: Blood Effect 30 | MF1: Clan Bane | MG1: Bloodline Bane | MH1: Other Bane 1 | MI1: Other Bane 2 | MJ1: Other Bane 3 | MK1: Clan Bane Effect | ML1: Bloodline Bane Effect | MM1: Other Bane Effect 1 | MN1: Other Bane Effect 2 | MO1: Other Bane Effect 3 | MP1: Size | MQ1: Speed | MR1: Defence | MS1: Mask 1WP | MT1: Mask AllWP | MU1: Dirge 1WP | MV1: Dirge AllWP | MW1: Aspiration 1 | MX1: Aspiration 2 | MY1: Aspiration 3 | MZ1: Apparent Age | NA1: Features
A2: tblCharDataAlice | B2: 46104 | C2: 9 | D2: 32 | E2: Katherine H | F2: Alice Vunder | G2: Curious archivist | H2: she/her | I2: Mekhet | J2: D:\Terra Mortis\Character Sheets\Sheet Elements\Mekhet icon.svg | K2: ¬ | L2: Circle of the Crone | M2: D:\Terra Mortis\Character Sheets\Sheet Elements\Crone icon.svg | N2: Follower | O2: Scholar | P2: Regent | Q2: ●●●● | R2: ●●● | S2: ●● | T2: ● | U2: ●●● | V2: ●● | W2: ●●● | X2: ●● | Y2: ●● | Z2: ●● | AA2: ●●● | AC2: ●●● | AE2: ●●● | AL2: ●● | AM2: ●● | AQ2: ●● | AR2: ●●● | AU2: ●● | AX2: ●○○○○○○○○○ | AY2: 1 | BA2: □□□□□□□■■■■■■■■ | BB2: 4 / 4 | BC2: □□□□■■■■■■ | BD2: 10 / 10 | BE2: □□□□□□□□□□■■■■■■■■■■ | BF2: 1 | BG2: Animals | BH2: Research | BI2: Hacking | BY2: Motives | CF2: 2 | CG2: 1 | CH2: 1 | CI2: Crone | CJ2: ● | CK2: Carthian | CL2: - | CM2: Invictus | CN2: - | CO2: Lance | CP2: - | CQ2: ● | CR2: ● | CS2: - | CT2: - | CU2: ●●●●● | CV2: The Archive | CW2: - | CY2: 6 | CZ2: ~ | DA2: ○ | DB2: ○ | DC2: ○ | DD2: ○ | DE2: ● (Sister (unnamed)) | DF2: ● (One parent (unnamed)) | DG2: ● | DH2: ● | DI2: ● | DJ2: ● | DK2: Hobbyist Clique ● | DL2: Library (Occult) ●● | DM2: Viral Mythology ●●● | DN2: ¬ | DO2: ¬ | DP2: ¬ | DQ2: ¬ | DR2: ¬ | DS2: ¬ | DT2: ¬ | DU2: ¬ | DV2: ¬ | DW2: ¬ | DX2: ¬ | DY2: ¬ | DZ2: ¬ | EA2: ¬ | EB2: ¬ | EC2: ¬ | ED2: ¬ | EE2: ¬ | EF2: ¬ | EG2: ¬ | EH2: ¬ | EI2: ¬ | EJ2: ¬ | EK2: ¬ | EL2: ¬ | EM2: ¬ | EN2: ¬ | EO2: 9-Again on hobby Skill; +2 to extended actions with that Skill. | EP2: Add dots to extended rolls for a chosen Skill's subject matter. | EQ2: Presence + Expression vs Wits + Composure to inflict contagious awe. Allies and Herd double their yield. | ER2: ¬ | ES2: ¬ | ET2: ¬ | EU2: ¬ | EV2: ¬ | EW2: ¬ | EX2: ¬ | EY2: ¬ | EZ2: ¬ | FA2: ¬ | FB2: ¬ | FC2: ¬ | FD2: ¬ | FE2: ¬ | FF2: ¬ | FG2: ¬ | FH2: ¬ | FI2: ¬ | FJ2: ¬ | FK2: ¬ | FL2: ¬ | FM2: ¬ | FN2: ¬ | FO2: ¬ | FP2: ¬ | FQ2: ¬ | FR2: ¬ | FS2: 8 / 8 | FT2: □□□□□□□□ | FU2: Allies | FV2: Allies | FW2: Allies | FX2: Allies | FY2: Contacts | FZ2: ¬ | GA2: ¬ | GB2: ¬ | GC2: ¬ | GD2: ¬ | GE2: ¬ | GF2: ¬ | GG2: ¬ | GH2: ¬ | GI2: ¬ | GJ2: ¬ | GK2: ¬ | GL2: ¬ | GM2: ¬ | GN2: ¬ | GO2: Health | GP2: Politics | GQ2: Transportation | GR2: Underworld | GS2: Street, Occult, Industry | GT2: ¬ | GU2: ¬ | GV2: ¬ | GW2: ¬ | GX2: ¬ | GY2: ¬ | GZ2: ¬ | HA2: ¬ | HB2: ¬ | HC2: ¬ | HD2: ¬ | HE2: ¬ | HF2: ¬ | HG2: ¬ | HH2: ¬ | HI2: ●●● | HJ2: ●●● | HK2: ●●● | HL2: ●●● | HM2: ●●● | IC2: - | ID2: ● | IE2: ● | IF2: - | IG2: - | IH2: - | II2: ●●● | IJ2: - | IK2: - | IL2: - | IM2: ● | IN2: - | IO2: ● | IP2: - | IQ2: ● | IR2: ● | IS2: - | IT2: Auspex ● | Beast's Hackles | IU2: Celerity ● | IV2: Obfuscate ● | Face in the Crowd | IW2: Obfuscate ●● | Touch of Shadow | IX2: Obfuscate ●●● | Cloak of Night | IY2: Blood Sorcery | Creation ● | IZ2: Blood Sorcery | Divination ● | JA2: Blood Sorcery | Protection ● | JB2: ¬ | JC2: ¬ | JD2: ¬ | JE2: ¬ | JF2: ¬ | JG2: ¬ | JH2: ¬ | JI2: ¬ | JJ2: ¬ | JK2: ¬ | JL2: ¬ | JM2: ¬ | JN2: ¬ | JO2: ¬ | JP2: ¬ | JQ2: ¬ | JR2: ¬ | JS2: ¬ | JT2: ¬ | JU2: ¬ | JV2: ¬ | JW2: ¬ | JX2: Cost: Free (1 V for Insight) • Pool: - - Composure & Closed Book • Instant • Scene | JY2: Cost: 1 V per effect • Pool: - • Reflexive • 1 turn | JZ2: Cost: - • Pool: - • Instant • Scene | KA2: Cost: 1 V • Pool: 8 • Instant • Scene | KB2: Cost: 1 V • Pool: - • None | KC2: ¬ | KD2: ¬ | KE2: ¬ | KF2: ¬ | KG2: ¬ | KH2: ¬ | KI2: ¬ | KJ2: ¬ | KK2: ¬ | KL2: ¬ | KM2: ¬ | KN2: ¬ | KO2: ¬ | KP2: ¬ | KQ2: ¬ | KR2: ¬ | KS2: ¬ | KT2: ¬ | KU2: ¬ | KV2: ¬ | KW2: ¬ | KX2: ¬ | KY2: ¬ | KZ2: ¬ | LA2: ¬ | LB2: Add Auspex dots to any rolls to resist surprise. Access to Tier 1 Auspex Insight questions. | LC2: Persistent improved Defence or Dodge. Activate for supernatural speed benefits. Unnatural Grace: add Celerity dots as bonus dice to non-combat speed-based pools. | LD2: Blend into surroundings, visible but unnoticeable. Predatory aura fully on or off. Leaving combat: Wits + Composure - Obfuscate to notice; auto Clash of Wills vs Auspex. | LE2: Cast Face in the Crowd on object or person. Free and unlimited duration on carried/worn objects if not drawing attention. | LF2: Become invisible. Leaving combat: auto Clash of Wills vs Auspex 2. | LG2: Summon liquids, dead organic matter, sensory phenomena. Bonus/penalty = Potency. | LH2: Glimpse fragmented details about intended actions. Learn basic info about a target. | LI2: Subtract Potency from ritual rolls targeting subject. Heal bashing in vampires. Protect from the Kiss (add Potency to resistance). | LJ2: ¬ | LK2: ¬ | LL2: ¬ | LM2: ¬ | LN2: ¬ | LO2: ¬ | LP2: ¬ | LQ2: ¬ | LR2: ¬ | LS2: ¬ | LT2: ¬ | LU2: ¬ | LV2: ¬ | LW2: ¬ | LX2: ¬ | LY2: ¬ | LZ2: ¬ | MA2: ¬ | MB2: ¬ | MC2: ¬ | MD2: ¬ | ME2: ¬ | MF2: Tenebrous Curse | MG2: ¬ | MH2: Rat King/Queen | MI2: ¬ | MJ2: ¬ | MK2: Gain an extra bane at Humanity 6 (doesn't count towards cap); Humanity counts –1 for all Humanity-based banes. | ML2: ¬ | MM2: Surrounded by vermin; all Social rolls fail except Intimidation; WP can dismiss. | MN2: ¬ | MO2: ¬ | MP2: 5 | MQ2: 9 | MR2: 3 | MS2: Follow a directive blindly, for the sake of following. | MT2: Follow a dangerous directive without hesitation. | MU2: Uncover a lost piece of information. | MV2: Uncover forbidden knowledge. | MW2: ¬ | MX2: ¬ | MY2: ¬
A3: tblCharDataAnichka | B3: 46104 | C3: 2 | D3: 28 | E3: Katie H | F3: Anichka | G3: Feral Oracular Darling | H3: she/her | I3: Mekhet | J3: D:\Terra Mortis\Character Sheets\Sheet Elements\Mekhet icon.svg | K3: ¬ | L3: Circle of the Crone | M3: D:\Terra Mortis\Character Sheets\Sheet Elements\Crone icon.svg | N3: Questioner | O3: Scholar | P3: ¬ | Q3: ●● | R3: ●●● | S3: ●●● | T3: ●● | U3: ●● | V3: ●● | W3: ●● | X3: ●●● | Y3: ●●● | AE3: ●●●● | AH3: ●● | AM3: ●● | AN3: ●●● | AP3: ●● | AQ3: ●●● | AR3: ●● | AT3: ●● | AU3: ● | AV3: ● | AX3: ●○○○○○○○○○ | AY3: 1 | BA3: □□□□□□□■■■■■■■■ | BB3: 6 / 6 | BC3: □□□□□□■■■■ | BD3: 9 / 10 | BE3: □□□□□□□□□■■■■■■■■■■■ | BF3: 1 | BG3: Animals | BM3: prophecy & omens, dreams | BV3: Living off the land | CF3: 2 | CG3: 2 | CH3: 4 | CI3: Crone | CJ3: ●●●● | CK3: Carthian | CL3: - | CM3: Invictus | CN3: - | CO3: Lance | CP3: - | CQ3: ● | CR3: ● | CS3: - | CT3: ●● | CU3: - | CW3: - | CY3: 6 | CZ3: ~ | DA3: ○ | DB3: ○ | DC3: ○ | DD3: ○ | DE3: ● (Kateryna (grand-niece)) | DF3: ● | DG3: ● | DH3: ● | DI3: ● | DJ3: ● | DK3: Dream Visions ● | DL3: Language ● | DM3: Language ● | DN3: Tolerance for Biology ● | DO3: What You've Done For Her Lately ● | DP3: ¬ | DQ3: ¬ | DR3: ¬ | DS3: ¬ | DT3: ¬ | DU3: ¬ | DV3: ¬ | DW3: ¬ | DX3: ¬ | DY3: ¬ | DZ3: ¬ | EA3: ¬ | EB3: ¬ | EC3: ¬ | ED3: ¬ | EE3: ¬ | EF3: ¬ | EG3: ¬ | EH3: ¬ | EI3: ¬ | EJ3: ¬ | EK3: ¬ | EL3: ¬ | EM3: ¬ | EN3: ¬ | EO3: Once per night, roll Blood Potency for prophetic dreams about a new person or place. | EP3: Speak, read and write a chosen language. | EQ3: Speak, read and write a chosen language. | ER3: Ignore Resistance rolls from witnessing biological grotesquerie. | ES3: Once per story, after a Crúac ritual, add ritual level to effective Crone Status for the chapter (Social rolls, favours, Social Merits until sunrise). | ET3: ¬ | EU3: ¬ | EV3: ¬ | EW3: ¬ | EX3: ¬ | EY3: ¬ | EZ3: ¬ | FA3: ¬ | FB3: ¬ | FC3: ¬ | FD3: ¬ | FE3: ¬ | FF3: ¬ | FG3: ¬ | FH3: ¬ | FI3: ¬ | FJ3: ¬ | FK3: ¬ | FL3: ¬ | FM3: ¬ | FN3: ¬ | FO3: ¬ | FP3: ¬ | FQ3: ¬ | FR3: ¬ | FS3: 7 / 7 | FT3: □□□□□□□ | FU3: Retainer | FV3: ¬ | FW3: ¬ | FX3: ¬ | FY3: ¬ | FZ3: ¬ | GA3: ¬ | GB3: ¬ | GC3: ¬ | GD3: ¬ | GE3: ¬ | GF3: ¬ | GG3: ¬ | GH3: ¬ | GI3: ¬ | GJ3: ¬ | GK3: ¬ | GL3: ¬ | GM3: ¬ | GN3: ¬ | GO3: family | GP3: ¬ | GQ3: ¬ | GR3: ¬ | GS3: ¬ | GT3: ¬ | GU3: ¬ | GV3: ¬ | GW3: ¬ | GX3: ¬ | GY3: ¬ | GZ3: ¬ | HA3: ¬ | HB3: ¬ | HC3: ¬ | HD3: ¬ | HE3: ¬ | HF3: ¬ | HG3: ¬ | HH3: ¬ | HI3: ●●● | IC3: - | ID3: ●● | IE3: - | IF3: - | IG3: - | IH3: - | II3: ● | IJ3: ● | IK3: - | IL3: - | IM3: ●●● | IN3: - | IO3: ● | IP3: - | IQ3: ●●● | IR3: ● | IS3: - | IT3: Auspex ● | Beast's Hackles | IU3: Auspex ●● | Uncanny Perception | IV3: Obfuscate ● | Face in the Crowd | IW3: Protean ● | Unmarked Grave | IX3: Blood Sorcery | Creation ● | IY3: Blood Sorcery | Divination ● | IZ3: Blood Sorcery | Divination ●● | JA3: Blood Sorcery | Divination ●●● | JB3: Blood Sorcery | Protection ● | JC3: Cruac ● | The Pool of Forbidden Truths | JD3: ¬ | JE3: ¬ | JF3: ¬ | JG3: ¬ | JH3: ¬ | JI3: ¬ | JJ3: ¬ | JK3: ¬ | JL3: ¬ | JM3: ¬ | JN3: ¬ | JO3: ¬ | JP3: ¬ | JQ3: ¬ | JR3: ¬ | JS3: ¬ | JT3: ¬ | JU3: ¬ | JV3: ¬ | JW3: ¬ | JX3: Cost: Free (1 V for Insight) • Pool: - - Composure & Closed Book • Instant • Scene | JY3: Cost: Free (1 V for Insight) Must perceive target • Pool: - • Instant • Scene | JZ3: Cost: - • Pool: - • Instant • Scene | KA3: Cost: Varies • Pool: - • Instant • Indefinite | KB3: ¬ | KC3: ¬ | KD3: ¬ | KE3: ¬ | KF3: ¬ | KG3: Cost: 1 V 1 Successes • Pool: 10 • Ritual • Instant | KH3: ¬ | KI3: ¬ | KJ3: ¬ | KK3: ¬ | KL3: ¬ | KM3: ¬ | KN3: ¬ | KO3: ¬ | KP3: ¬ | KQ3: ¬ | KR3: ¬ | KS3: ¬ | KT3: ¬ | KU3: ¬ | KV3: ¬ | KW3: ¬ | KX3: ¬ | KY3: ¬ | KZ3: ¬ | LA3: ¬ | LB3: Add Auspex dots to any rolls to resist surprise. Access to Tier 1 Auspex Insight questions. | LC3: Persistent Acute Senses Merit, doubles actual merit. Access to Tier 2 Auspex Insight questions. | LD3: Blend into surroundings, visible but unnoticeable. Predatory aura fully on or off. Leaving combat: Wits + Composure - Obfuscate to notice; auto Clash of Wills vs Auspex. | LE3: Merge with soil. | LF3: Summon liquids, dead organic matter, sensory phenomena. Bonus/penalty = Potency. | LG3: Glimpse fragmented details about intended actions. Learn basic info about a target. | LH3: Ask specific questions about a target. Sense supernatural concealment on objects. Detect lies. | LI3: View past events (limited by Fog of Eternity). Locate hidden targets. Prophetic omens about near future. | LJ3: Subtract Potency from ritual rolls targeting subject. Heal bashing in vampires. Protect from the Kiss (add Potency to resistance). | LK3: Blood pool reveals subject's greatest fear or deepest desire | LL3: ¬ | LM3: ¬ | LN3: ¬ | LO3: ¬ | LP3: ¬ | LQ3: ¬ | LR3: ¬ | LS3: ¬ | LT3: ¬ | LU3: ¬ | LV3: ¬ | LW3: ¬ | LX3: ¬ | LY3: ¬ | LZ3: ¬ | MA3: ¬ | MB3: ¬ | MC3: ¬ | MD3: ¬ | ME3: ¬ | MF3: Tenebrous Curse | MG3: ¬ | MH3: ¬ | MI3: ¬ | MJ3: ¬ | MK3: Gain an extra bane at Humanity 6 (doesn't count towards cap); Humanity counts –1 for all Humanity-based banes. | ML3: ¬ | MN3: ¬ | MO3: ¬ | MP3: 5 | MQ3: 9 | MR3: 4 | MS3: Challenge an accepted truth. | MT3: Put a long-believed truth to the test, at your own peril. | MU3: Uncover a lost piece of information. | MV3: Uncover forbidden knowledge. | MW3: ¬ | MX3: ¬ | MY3: ¬ | MZ3: early 20s | NA3: smells like animals
A4: tblCharDataBrandy | B4: 46104 | C4: 1 | D4: 46 | E4: Ashley K | F4: Brandy LaRoux | G4: Trailer Royalty | H4: she/her | I4: Gangrel | J4: D:\Terra Mortis\Character Sheets\Sheet Elements\Gangrel icon.svg | K4: ¬ | L4: Circle of the Crone | M4: D:\Terra Mortis\Character Sheets\Sheet Elements\Crone icon.svg | N4: Perfectionist | O4: Monster | P4: Harpy | Q4: ●● | R4: ●● | S4: ●●● | T4: ●●● | U4: ●● | V4: ●●● | W4: ●●● | X4: ●● | Y4: ●●● | AB4: ● | AE4: ●●● | AI4: ●●●●● | AM4: ● | AN4: ● | AQ4: ●●● | AR4: ●● | AS4: ●●● | AT4: ● | AU4: ● | AW4: ● | AX4: ●○○○○○○○○○ | AY4: 1 | BA4: □□□□□□□□■■■■■■■ | BB4: 6 / 6 | BC4: □□□□□□■■■■ | BD4: 10 / 10 | BE4: □□□□□□□□□□■■■■■■■■■■ | BF4: 1 | BG4: Animals | BM4: Vodun | BQ4: Tooth & Claw | CE4: Put on airs | CF4: 4 | CG4: 2 | CH4: 2 | CI4: Crone | CJ4: ●● | CK4: Carthian | CL4: - | CM4: Invictus | CN4: - | CO4: Lance | CP4: - | CQ4: - | CR4: - | CS4: - | CT4: - | CU4: ●●●●● | CV4: Ducen Ducibus | CW4: - | CY4: 5 | CZ4: ~ | DA4: ○ | DB4: ○ | DC4: ○ | DD4: ○ | DE4: ○ (Tod Graves (husband)) | DF4: ● (Good Luck Molly (alligator)) | DG4: ● | DH4: ● | DI4: ● | DJ4: ● | DK4: Defensive Combat (Brawl) ● | DL4: Indomitable ●● | DM4: Inspiring ●●● | DN4: Meditative Mind ●● | DO4: Secret Society Junkie ● | DP4: Table Turner ● | DQ4: Viral Mythology ●●● | DR4: Riding the Wave ● | Ravage | DS4: Riding the Wave ●● | Primal Strength | DT4: Riding the Wave ●●● | In the Zone | DU4: Riding the Wave ●●●● | Unyielding | DV4: ¬ | DW4: ¬ | DX4: ¬ | DY4: ¬ | DZ4: ¬ | EA4: ¬ | EB4: ¬ | EC4: ¬ | ED4: ¬ | EE4: ¬ | EF4: ¬ | EG4: ¬ | EH4: ¬ | EI4: ¬ | EJ4: ¬ | EK4: ¬ | EL4: ¬ | EM4: ¬ | EN4: ¬ | EO4: Substitute chosen Skill for Athletics in Defence, if equipped for that Skill. | EP4: +2 to contest or resist supernatural mental influence. | EQ4: Roll Presence + Expression to confer the Inspired Condition. | ER4: Ignore penalties on meditation. (••) meditation grants +3 Resolve + Composure for the day. (••••) meditation needs only one success. | ES4: Dots in Status or Mystery Cult Initiation representing human secret societies also count as dots of Herd. | ET4: Spend Willpower to preempt Social Manoeuvring with your own Social action. | EU4: Presence + Expression vs Wits + Composure to inflict contagious awe. Allies and Herd double their yield. | EV4: Bite attacks take a 1L weapon rating. | EW4: Double your Strength bonus from frenzy when lifting, jumping, or destroying objects. | EX4: When you spend Willpower to ride the wave, you also apply the normal +3 action bonus. | EY4: After a scene where you rode the wave, recover any Willpower spent to do so. | EZ4: ¬ | FA4: ¬ | FB4: ¬ | FC4: ¬ | FD4: ¬ | FE4: ¬ | FF4: ¬ | FG4: ¬ | FH4: ¬ | FI4: ¬ | FJ4: ¬ | FK4: ¬ | FL4: ¬ | FM4: ¬ | FN4: ¬ | FO4: ¬ | FP4: ¬ | FQ4: ¬ | FR4: ¬ | FS4: 11 / 11 | FT4: □□□□□□□□□□□ | FU4: Allies | FV4: Allies | FW4: Allies | FX4: Allies | FY4: Resources | FZ4: ¬ | GA4: ¬ | GB4: ¬ | GC4: ¬ | GD4: ¬ | GE4: ¬ | GF4: ¬ | GG4: ¬ | GH4: ¬ | GI4: ¬ | GJ4: ¬ | GK4: ¬ | GL4: ¬ | GM4: ¬ | GN4: ¬ | GO4: High Society | GP4: Media | GQ4: Police | GR4: Underworld | GS4: ¬ | GT4: ¬ | GU4: ¬ | GV4: ¬ | GW4: ¬ | GX4: ¬ | GY4: ¬ | GZ4: ¬ | HA4: ¬ | HB4: ¬ | HC4: ¬ | HD4: ¬ | HE4: ¬ | HF4: ¬ | HG4: ¬ | HH4: ¬ | HI4: ●●● | HJ4: ●●● | HK4: ●●● | HL4: ●●● | HM4: ●●●●● | IC4: - | ID4: - | IE4: - | IF4: - | IG4: ● | IH4: - | II4: - | IJ4: ●●● | IK4: - | IL4: - | IM4: ● | IN4: - | IO4: ● | IP4: ● | IQ4: - | IR4: ● | IS4: - | IT4: Majesty ● | Awe | IU4: Protean ● | Unmarked Grave | IV4: Protean ●● | Predatory Aspect | IW4: Protean ●●● | Beast's Skin | IX4: Blood Sorcery | Creation ● | IY4: Blood Sorcery | Destruction ● | IZ4: Blood Sorcery | Protection ● | JA4: Cruac ● | Mantle of Amorous Fire | JB4: ¬ | JC4: ¬ | JD4: ¬ | JE4: ¬ | JF4: ¬ | JG4: ¬ | JH4: ¬ | JI4: ¬ | JJ4: ¬ | JK4: ¬ | JL4: ¬ | JM4: ¬ | JN4: ¬ | JO4: ¬ | JP4: ¬ | JQ4: ¬ | JR4: ¬ | JS4: ¬ | JT4: ¬ | JU4: ¬ | JV4: ¬ | JW4: ¬ | JX4: Cost: - • Pool: - • Instant • Scene | JY4: Cost: Varies • Pool: - • Instant • Indefinite | JZ4: Cost: 1 V • Pool: - • Instant • Scene | KA4: Cost: 2 V • Pool: - • Instant • Indefinite | KB4: ¬ | KC4: ¬ | KD4: ¬ | KE4: Cost: 1 V 1 Successes • Pool: 6 • Ritual • Scene | KF4: ¬ | KG4: ¬ | KH4: ¬ | KI4: ¬ | KJ4: ¬ | KK4: ¬ | KL4: ¬ | KM4: ¬ | KN4: ¬ | KO4: ¬ | KP4: ¬ | KQ4: ¬ | KR4: ¬ | KS4: ¬ | KT4: ¬ | KU4: ¬ | KV4: ¬ | KW4: ¬ | KX4: ¬ | KY4: ¬ | KZ4: ¬ | LA4: ¬ | LB4: Become centre of attention. Subjects become Awed. | LC4: Merge with soil. | LD4: Take on animal traits. | LE4: Transform into predatory animal. | LF4: Summon liquids, dead organic matter, sensory phenomena. Bonus/penalty = Potency. | LG4: Upgrade bashing to lethal. Produce poisons (Toxicity = Potency). | LH4: Subtract Potency from ritual rolls targeting subject. Heal bashing in vampires. Protect from the Kiss (add Potency to resistance). | LI4: Dance to exhaustion. Add Cruac as a Presence bonus for the night. | LJ4: ¬ | LK4: ¬ | LL4: ¬ | LM4: ¬ | LN4: ¬ | LO4: ¬ | LP4: ¬ | LQ4: ¬ | LR4: ¬ | LS4: ¬ | LT4: ¬ | LU4: ¬ | LV4: ¬ | LW4: ¬ | LX4: ¬ | LY4: ¬ | LZ4: ¬ | MA4: ¬ | MB4: ¬ | MC4: ¬ | MD4: ¬ | ME4: ¬ | MF4: Feral Curse | MG4: ¬ | MH4: ¬ | MI4: ¬ | MJ4: ¬ | MK4: Frenzy resistance dice pools capped by Humanity (doesn't affect Riding the Wave). | ML4: ¬ | MN4: ¬ | MO4: ¬ | MP4: 5 | MQ4: 10 | MR4: 2 | MS4: Revisit an already successful action to hammer out a flaw. | MT4: Stick with a failed and dangerous plan in order to fix what went wrong. | MU4: Cause pain for the sole intention of causing pain. | MV4: Commit a capital crime without additional motive. | MW4: ¬ | MX4: ¬ | MY4: ¬
A5: tblCharDataCarver | B5: 46104 | C5: 2 | D5: 50 | E5: Archer | F5: Carver | G5: Lance Lore Nerd | H5: he/him | I5: Ventrue | J5: D:\Terra Mortis\Character Sheets\Sheet Elements\Ventrue icon.svg | K5: Lasombra | L5: Lancea et Sanctum | M5: D:\Terra Mortis\Character Sheets\Sheet Elements\Lance icon.svg | N5: Scholar | O5: Authoritarian | P5: ¬ | Q5: ●●● | R5: ●● | S5: ●●● | T5: ●● | U5: ●● | V5: ●●○○ | W5: ●●● | X5: ●● | Y5: ●●● | Z5: ●●●● | AC5: ●● | AE5: ●●●● | AF5: ● | AL5: ●● | AM5: ●● | AQ5: ●●● | AS5: ●● | AT5: ●● | AX5: ●●○○○○○○○○ | AY5: 2 | AZ5: † | BA5: □□□□□□□□□■■■■■■ | BB5: 6 / 6 | BC5: □□□□□□■■■■ | BD5: 11 / 11 | BE5: □□□□□□□□□□□■■■■■■■■■ | BF5: 2 | BG5: Animals | BH5: law | BM5: artefacts | BY5: motives | CF5: 1 | CG5: 2 | CH5: 3 | CI5: Lance | CJ5: ●●● | CK5: Carthian | CL5: - | CM5: Crone | CN5: - | CO5: Invictus | CP5: - | CQ5: ●●●●● | CR5: ●●● | CS5: - | CT5: ●●● | CU5: - | CW5: - | CY5: 6 | CZ5: ~ | DA5: ○ | DB5: ○ | DC5: ○ | DD5: ○ (James (Crowley descendant)) | DE5: ● | DF5: ● | DG5: ● | DH5: ● | DI5: ● | DJ5: ● | DK5: Acute Senses ● | DL5: Eidetic Memory ● | DM5: Esoteric Armoury ● | DN5: Library (Academic) ●●● | DO5: Library (Occult) ●●● | DP5: Lorekeeper ● | DQ5: ¬ | DR5: ¬ | DS5: ¬ | DT5: ¬ | DU5: ¬ | DV5: ¬ | DW5: ¬ | DX5: ¬ | DY5: ¬ | DZ5: ¬ | EA5: ¬ | EB5: ¬ | EC5: ¬ | ED5: ¬ | EE5: ¬ | EF5: ¬ | EG5: ¬ | EH5: ¬ | EI5: ¬ | EJ5: ¬ | EK5: ¬ | EL5: ¬ | EM5: ¬ | EN5: ¬ | EO5: Add Blood Potency to sensory rolls. Exceptional success can inflict Obsession. | EP5: No rolls for recall. +2 to recall minute facts. | EQ5: Enough esoterica to supply the banes of ephemeral entities with a Rank up to your rating in this Merit. | ER5: Add dots to extended rolls for a chosen Skill's subject matter. | ES5: Add dots to extended rolls for a chosen Skill's subject matter. | ET5: Distribute Library dots among bonus Retainer and Herd. | EU5: ¬ | EV5: ¬ | EW5: ¬ | EX5: ¬ | EY5: ¬ | EZ5: ¬ | FA5: ¬ | FB5: ¬ | FC5: ¬ | FD5: ¬ | FE5: ¬ | FF5: ¬ | FG5: ¬ | FH5: ¬ | FI5: ¬ | FJ5: ¬ | FK5: ¬ | FL5: ¬ | FM5: ¬ | FN5: ¬ | FO5: ¬ | FP5: ¬ | FQ5: ¬ | FR5: ¬ | FS5: 7 / 7 | FT5: □□□□□□□ | FU5: Contacts | FV5: Resources | FW5: Retainer | FX5: ¬ | FY5: ¬ | FZ5: ¬ | GA5: ¬ | GB5: ¬ | GC5: ¬ | GD5: ¬ | GE5: ¬ | GF5: ¬ | GG5: ¬ | GH5: ¬ | GI5: ¬ | GJ5: ¬ | GK5: ¬ | GL5: ¬ | GM5: ¬ | GN5: ¬ | GO5: Occult, University, Beuracracy, Church, Legal | GP5: ¬ | GQ5: Nicole - EA | GR5: ¬ | GS5: ¬ | GT5: ¬ | GU5: ¬ | GV5: ¬ | GW5: ¬ | GX5: ¬ | GY5: ¬ | GZ5: ¬ | HA5: ¬ | HB5: ¬ | HC5: ¬ | HD5: ¬ | HE5: ¬ | HF5: ¬ | HG5: ¬ | HH5: ¬ | HI5: ●●●●● | HJ5: ●●● | HK5: ●●● | IC5: - | ID5: - | IE5: - | IF5: - | IG5: - | IH5: ●●●● | II5: - | IJ5: - | IK5: ●● | IL5: - | IM5: - | IN5: - | IO5: - | IP5: - | IQ5: - | IR5: - | IS5: - | IT5: Nightmare ● | Dread Presence | IU5: Nightmare ●● | Face of the Beast | IV5: Nightmare ●●● | Grand Delusion | IW5: Nightmare ●●●● | Waking Nightmare | IX5: Resilience ●● | IY5: Devotion | Skim the Void | IZ5: ¬ | JA5: ¬ | JB5: ¬ | JC5: ¬ | JD5: ¬ | JE5: ¬ | JF5: ¬ | JG5: ¬ | JH5: ¬ | JI5: ¬ | JJ5: ¬ | JK5: ¬ | JL5: ¬ | JM5: ¬ | JN5: ¬ | JO5: ¬ | JP5: ¬ | JQ5: ¬ | JR5: ¬ | JS5: ¬ | JT5: ¬ | JU5: ¬ | JV5: ¬ | JW5: ¬ | JX5: Cost: - • Pool: - • Instant • Scene | JY5: Cost: 1 V • Pool: 10 v Composure + BP • Contested • Instant | JZ5: Cost: 2 V • Pool: 9 v Composure + BP • Contested • 1 night | KA5: Cost: 1 V • Pool: 10 v highest Composure + BP • Contested • Scene | KB5: Cost: 1 V per effect • Pool: - • Reflexive • 1 turn | KC5: Cost: 1 V (Lasombra Only) • Pool: 6 • Instant • Instant | KD5: ¬ | KE5: ¬ | KF5: ¬ | KG5: ¬ | KH5: ¬ | KI5: ¬ | KJ5: ¬ | KK5: ¬ | KL5: ¬ | KM5: ¬ | KN5: ¬ | KO5: ¬ | KP5: ¬ | KQ5: ¬ | KR5: ¬ | KS5: ¬ | KT5: ¬ | KU5: ¬ | KV5: ¬ | KW5: ¬ | KX5: ¬ | KY5: ¬ | KZ5: ¬ | LA5: ¬ | LB5: Conjure brief illusions. Improve Intimidation. Prevent foes spending Willpower. | LC5: Impose Frightened Condition. Cause fleeing. | LD5: Impose Delusional Condition. | LE5: Create and control hallucinations. | LF5: Downgrade damage and increase Stamina. Improve Armour and Defences. Unnatural Fortitude: add Resilience dots as bonus dice to non-combat Stamina pools. | LG5: Step into any visible shadow and out of another instantly. Can carry objects but not people or animals. Torpid Kindred do not count as objects. | LH5: ¬ | LI5: ¬ | LJ5: ¬ | LK5: ¬ | LL5: ¬ | LM5: ¬ | LN5: ¬ | LO5: ¬ | LP5: ¬ | LQ5: ¬ | LR5: ¬ | LS5: ¬ | LT5: ¬ | LU5: ¬ | LV5: ¬ | LW5: ¬ | LX5: ¬ | LY5: ¬ | LZ5: ¬ | MA5: ¬ | MB5: ¬ | MC5: ¬ | MD5: ¬ | ME5: ¬ | MF5: Aloof Curse | MG5: ¬ | MH5: ¬ | MI5: ¬ | MJ5: ¬ | MK5: First Touchstone attaches to Humanity 7; losing it detaches on first Humanity loss. Breaking points always treated as one step lower. | ML5: ¬ | MN5: ¬ | MO5: ¬ | MP5: 5 | MQ5: 9 | MR5: 2 | MS5: Uncover a lost piece of information. | MT5: Uncover forbidden knowledge. | MU5: Cow someone into submission. | MV5: Commit a widespread hit against a rival's mortal connections. | MW5: ¬ | MX5: ¬ | MY5: ¬ | MZ5: mid 40s
A6: tblCharDataCazz | B6: 46104 | C6: 4 | D6: 34 | E6: Brae C | F6: Casamir 'Cazz' | G6: The Mad Dog | H6: he/they | I6: Ventrue | J6: D:\Terra Mortis\Character Sheets\Sheet Elements\Ventrue icon.svg | K6: Malkovians | L6: Carthian Movement | M6: D:\Terra Mortis\Character Sheets\Sheet Elements\Carthian icon.svg | N6: Scholar | O6: Jester | P6: ¬ | Q6: ●●● | R6: ●●● | S6: ●●● | T6: ●●● | U6: ●●● | V6: ●●●○ | W6: ●● | X6: ●● | Y6: ●● | Z6: ●● | AB6: ● | AC6: ● | AE6: ●● | AG6: ● | AH6: ●●●●● | AK6: ●●● | AL6: ● | AM6: ● | AN6: ● | AQ6: ● | AS6: ● | AW6: ●● | AX6: ●●○○○○○○○○ | AY6: 2 | AZ6: † | BA6: □□□□□□□□□■■■■■■ | BB6: 5 / 5 | BC6: □□□□□■■■■■ | BD6: 11 / 11 | BE6: □□□□□□□□□□□■■■■■■■■■ | BF6: 2 | BG6: Animals | BM6: ley lines | BP6: endurance | BS6: archery | CF6: 1 | CG6: 1 | CH6: 1 | CI6: Carthian | CJ6: ● | CK6: Crone | CL6: - | CM6: Invictus | CN6: - | CO6: Lance | CP6: - | CQ6: ● | CR6: - | CS6: - | CT6: ● | CU6: - | CW6: - | CY6: 6 | CZ6: ~ | DA6: ○ | DB6: ○ | DC6: ○ | DD6: ○ (University testamur (Simulacrum)) | DE6: ● | DF6: ● | DG6: ● | DH6: ● | DI6: ● | DJ6: ● | DK6: Quick Draw (Bow) ● | DL6: Combat Archery ● | Rapid Nock | DM6: Combat Archery ●● | Reflex Aiming | DN6: Combat Archery ●●● | Parthian Shot | DO6: Combat Archery ●●●● | Rain of Arrows | DP6: Combat Archery ●●●●● | Trick Shot | DQ6: ¬ | DR6: ¬ | DS6: ¬ | DT6: ¬ | DU6: ¬ | DV6: ¬ | DW6: ¬ | DX6: ¬ | DY6: ¬ | DZ6: ¬ | EA6: ¬ | EB6: ¬ | EC6: ¬ | ED6: ¬ | EE6: ¬ | EF6: ¬ | EG6: ¬ | EH6: ¬ | EI6: ¬ | EJ6: ¬ | EK6: ¬ | EL6: ¬ | EM6: ¬ | EN6: ¬ | EO6: Draw a weapon from a chosen Specialty reflexively while Defence is available. Initiative bonuses only apply if using the weapon. | EP6: Ignore bow Initiative penalties. String arrows reflexively. | EQ6: Ignore penalties for firing into close combat. | ER6: When you Dodge, inflict threshold successes as attack damage against the first close attack you beat each turn. | ES6: Make medium autofire attacks at triple range penalties. | ET6: Simultaneously perform a Combat Archery attack and an Athletics action, both at -2. | EU6: ¬ | EV6: ¬ | EW6: ¬ | EX6: ¬ | EY6: ¬ | EZ6: ¬ | FA6: ¬ | FB6: ¬ | FC6: ¬ | FD6: ¬ | FE6: ¬ | FF6: ¬ | FG6: ¬ | FH6: ¬ | FI6: ¬ | FJ6: ¬ | FK6: ¬ | FL6: ¬ | FM6: ¬ | FN6: ¬ | FO6: ¬ | FP6: ¬ | FQ6: ¬ | FR6: ¬ | FS6: 0 / 2 | FT6: ■■ | FU6: ¬ | FV6: ¬ | FW6: ¬ | FX6: ¬ | FY6: ¬ | FZ6: ¬ | GA6: ¬ | GB6: ¬ | GC6: ¬ | GD6: ¬ | GE6: ¬ | GF6: ¬ | GG6: ¬ | GH6: ¬ | GI6: ¬ | GJ6: ¬ | GK6: ¬ | GL6: ¬ | GM6: ¬ | GN6: ¬ | GO6: ¬ | GP6: ¬ | GQ6: ¬ | GR6: ¬ | GS6: ¬ | GT6: ¬ | GU6: ¬ | GV6: ¬ | GW6: ¬ | GX6: ¬ | GY6: ¬ | GZ6: ¬ | HA6: ¬ | HB6: ¬ | HC6: ¬ | HD6: ¬ | HE6: ¬ | HF6: ¬ | HG6: ¬ | HH6: ¬ | IC6: - | ID6: ● | IE6: ● | IF6: - | IG6: - | IH6: - | II6: ● | IJ6: - | IK6: ● | IL6: - | IM6: - | IN6: - | IO6: - | IP6: - | IQ6: - | IR6: - | IS6: - | IT6: Auspex ● | Beast's Hackles | IU6: Celerity ● | IV6: Obfuscate ● | Face in the Crowd | IW6: Resilience ● | IX6: ¬ | IY6: ¬ | IZ6: ¬ | JA6: ¬ | JB6: ¬ | JC6: ¬ | JD6: ¬ | JE6: ¬ | JF6: ¬ | JG6: ¬ | JH6: ¬ | JI6: ¬ | JJ6: ¬ | JK6: ¬ | JL6: ¬ | JM6: ¬ | JN6: ¬ | JO6: ¬ | JP6: ¬ | JQ6: ¬ | JR6: ¬ | JS6: ¬ | JT6: ¬ | JU6: ¬ | JV6: ¬ | JW6: ¬ | JX6: Cost: Free (1 V for Insight) • Pool: - - Composure & Closed Book • Instant • Scene | JY6: Cost: 1 V per effect • Pool: - • Reflexive • 1 turn | JZ6: Cost: - • Pool: - • Instant • Scene | KA6: Cost: 1 V per effect • Pool: - • Reflexive • 1 turn | KB6: ¬ | KC6: ¬ | KD6: ¬ | KE6: ¬ | KF6: ¬ | KG6: ¬ | KH6: ¬ | KI6: ¬ | KJ6: ¬ | KK6: ¬ | KL6: ¬ | KM6: ¬ | KN6: ¬ | KO6: ¬ | KP6: ¬ | KQ6: ¬ | KR6: ¬ | KS6: ¬ | KT6: ¬ | KU6: ¬ | KV6: ¬ | KW6: ¬ | KX6: ¬ | KY6: ¬ | KZ6: ¬ | LA6: ¬ | LB6: Add Auspex dots to any rolls to resist surprise. Access to Tier 1 Auspex Insight questions. | LC6: Persistent improved Defence or Dodge. Activate for supernatural speed benefits. Unnatural Grace: add Celerity dots as bonus dice to non-combat speed-based pools. | LD6: Blend into surroundings, visible but unnoticeable. Predatory aura fully on or off. Leaving combat: Wits + Composure - Obfuscate to notice; auto Clash of Wills vs Auspex. | LE6: Downgrade damage and increase Stamina. Improve Armour and Defences. Unnatural Fortitude: add Resilience dots as bonus dice to non-combat Stamina pools. | LF6: ¬ | LG6: ¬ | LH6: ¬ | LI6: ¬ | LJ6: ¬ | LK6: ¬ | LL6: ¬ | LM6: ¬ | LN6: ¬ | LO6: ¬ | LP6: ¬ | LQ6: ¬ | LR6: ¬ | LS6: ¬ | LT6: ¬ | LU6: ¬ | LV6: ¬ | LW6: ¬ | LX6: ¬ | LY6: ¬ | LZ6: ¬ | MA6: ¬ | MB6: ¬ | MC6: ¬ | MD6: ¬ | ME6: ¬ | MF6: Aloof Curse | MG6: ¬ | MH6: ¬ | MI6: ¬ | MJ6: ¬ | MK6: First Touchstone attaches to Humanity 7; losing it detaches on first Humanity loss. Breaking points always treated as one step lower. | ML6: ¬ | MN6: ¬ | MO6: ¬ | MP6: 5 | MQ6: 11 | MR6: 8 | MS6: Uncover a lost piece of information. | MT6: Uncover forbidden knowledge. | MU6: Point out an absurdity in the current state of affairs to lighten the tone. | MV6: Favour wit and cunning over direct self-defence in a situation of serious danger. | MW6: ¬ | MX6: ¬ | MY6: ¬ | MZ6: mid 30s
A7: tblCharDataCharles | B7: 46104 | C7: 1 | D7: 30 | E7: Leo T | F7: Charles Mercer-Willows | G7: Cult Leader | H7: he/him | I7: Ventrue | J7: D:\Terra Mortis\Character Sheets\Sheet Elements\Ventrue icon.svg | K7: Gorgons | L7: Circle of the Crone | M7: D:\Terra Mortis\Character Sheets\Sheet Elements\Crone icon.svg | N7: Nurturer | O7: Cult Leader | P7: ¬ | Q7: ●● | R7: ●●● | S7: ●●● | T7: ●● | U7: ●● | V7: ●● | W7: ●●● | X7: ●●● | Y7: ●● | AA7: ● | AB7: ●●● | AE7: ●●● | AH7: ● | AK7: ●● | AL7: ● | AP7: ● | AQ7: ● | AR7: ●●●● | AT7: ●●● | AU7: ● | AW7: ●● | AX7: ●○○○○○○○○○ | AY7: 1 | BA7: □□□□□□□■■■■■■■■ | BB7: 5 / 5 | BC7: □□□□□■■■■■ | BD7: 9 / 10 | BE7: □□□□□□□□□■■■■■■■■■■■ | BF7: 1 | BG7: Animals | BJ7: sculpting | BM7: Judeo-Christian Lore | BS7: rifles | BZ7: oratory | CF7: 2 | CG7: 2 | CH7: 3 | CI7: Crone | CJ7: ●●● | CK7: Carthian | CL7: - | CM7: Invictus | CN7: - | CO7: Lance | CP7: - | CQ7: ● | CR7: ● | CS7: - | CT7: ●●●●● | CU7: ●●●●● | CV7: <NAME REQUIRED> | CW7: - | CY7: 5 | CZ7: ~ | DA7: ○ | DB7: ○ | DC7: ○ | DD7: ○ (Ezekiel (Son)) | DE7: ○ (Unnamed congregant) | DF7: ● | DG7: ● | DH7: ● | DI7: ● | DJ7: ● | DK7: Closed Book ● | DL7: Inspiring ●●● | DM7: Secret Society Junkie ● | DN7: Viral Mythology ●●● | DO7: ¬ | DP7: ¬ | DQ7: ¬ | DR7: ¬ | DS7: ¬ | DT7: ¬ | DU7: ¬ | DV7: ¬ | DW7: ¬ | DX7: ¬ | DY7: ¬ | DZ7: ¬ | EA7: ¬ | EB7: ¬ | EC7: ¬ | ED7: ¬ | EE7: ¬ | EF7: ¬ | EG7: ¬ | EH7: ¬ | EI7: ¬ | EJ7: ¬ | EK7: ¬ | EL7: ¬ | EM7: ¬ | EN7: ¬ | EO7: Add dots to Doors and as bonus to contest Social assessments. | EP7: Roll Presence + Expression to confer the Inspired Condition. | EQ7: Dots in Status or Mystery Cult Initiation representing human secret societies also count as dots of Herd. | ER7: Presence + Expression vs Wits + Composure to inflict contagious awe. Allies and Herd double their yield. | ES7: ¬ | ET7: ¬ | EU7: ¬ | EV7: ¬ | EW7: ¬ | EX7: ¬ | EY7: ¬ | EZ7: ¬ | FA7: ¬ | FB7: ¬ | FC7: ¬ | FD7: ¬ | FE7: ¬ | FF7: ¬ | FG7: ¬ | FH7: ¬ | FI7: ¬ | FJ7: ¬ | FK7: ¬ | FL7: ¬ | FM7: ¬ | FN7: ¬ | FO7: ¬ | FP7: ¬ | FQ7: ¬ | FR7: ¬ | FS7: 5 / 5 | FT7: □□□□□ | FU7: Allies | FV7: Allies | FW7: Allies | FX7: Allies | FY7: Resources | FZ7: ¬ | GA7: ¬ | GB7: ¬ | GC7: ¬ | GD7: ¬ | GE7: ¬ | GF7: ¬ | GG7: ¬ | GH7: ¬ | GI7: ¬ | GJ7: ¬ | GK7: ¬ | GL7: ¬ | GM7: ¬ | GN7: ¬ | GO7: Legal | GP7: Media | GQ7: Occult | GR7: Underworld | GS7: ¬ | GT7: ¬ | GU7: ¬ | GV7: ¬ | GW7: ¬ | GX7: ¬ | GY7: ¬ | GZ7: ¬ | HA7: ¬ | HB7: ¬ | HC7: ¬ | HD7: ¬ | HE7: ¬ | HF7: ¬ | HG7: ¬ | HH7: ¬ | HI7: ●●● | HJ7: ●●● | HK7: ●●● | HL7: ●●● | HM7: ● | IC7: ● | ID7: - | IE7: - | IF7: ●● | IG7: - | IH7: - | II7: - | IJ7: ●● | IK7: - | IL7: - | IM7: ●● | IN7: - | IO7: ●● | IP7: - | IQ7: - | IR7: ● | IS7: ● | IT7: Animalism ● | Feral Whispers | IU7: Dominate ● | Mesmerise | IV7: Dominate ●● | Iron Edict | IW7: Protean ● | Unmarked Grave | IX7: Protean ●● | Predatory Aspect | IY7: Blood Sorcery | Creation ● | IZ7: Blood Sorcery | Creation ●● | JA7: Blood Sorcery | Protection ● | JB7: Blood Sorcery | Transmutation ● | JC7: Cruac ● | Fires of Inspiration | JD7: Cruac ●● | Wisdom of the Soul | JE7: ¬ | JF7: ¬ | JG7: ¬ | JH7: ¬ | JI7: ¬ | JJ7: ¬ | JK7: ¬ | JL7: ¬ | JM7: ¬ | JN7: ¬ | JO7: ¬ | JP7: ¬ | JQ7: ¬ | JR7: ¬ | JS7: ¬ | JT7: ¬ | JU7: ¬ | JV7: ¬ | JW7: ¬ | JX7: Cost: - • Pool: 5 • Instant • Scene (may persist) | JY7: Cost: - -3 in combat unless Blinded • Pool: 8 v Resolve + BP • Instant • Instant | JZ7: Cost: 1 V (0 in bond) (req: Mesmerised); -3 in combat unless Blinded • Pool: - • Instant • Instant | KA7: Cost: Varies • Pool: - • Instant • Indefinite | KB7: Cost: 1 V • Pool: - • Instant • Scene | KC7: ¬ | KD7: ¬ | KE7: ¬ | KF7: ¬ | KG7: Cost: 1 V 1 Successes • Pool: 8 • Ritual • 1 night | KH7: Cost: 1 V 2 Successes • Pool: 8 • Ritual • Instant | KI7: ¬ | KJ7: ¬ | KK7: ¬ | KL7: ¬ | KM7: ¬ | KN7: ¬ | KO7: ¬ | KP7: ¬ | KQ7: ¬ | KR7: ¬ | KS7: ¬ | KT7: ¬ | KU7: ¬ | KV7: ¬ | KW7: ¬ | KX7: ¬ | KY7: ¬ | KZ7: ¬ | LA7: ¬ | LB7: Speak with and command animals. | LC7: Impose Mesmerised Condition. Control with short commands. | LD7: Impose Dominated Condition. Give long, detailed commands. | LE7: Merge with soil. | LF7: Take on animal traits. | LG7: Summon liquids, dead organic matter, sensory phenomena. Bonus/penalty = Potency. | LH7: Summon living insects, vermin, amphibians, fungi, plants, drugs, gases. Under mental command while concentrating. | LI7: Subtract Potency from ritual rolls targeting subject. Heal bashing in vampires. Protect from the Kiss (add Potency to resistance). | LJ7: Minor cosmetic changes to living subjects. Warp dead matter. Animate liquids. | LK7: Gain dots in Cruac to Craft or Expression to create a specific work of art, but penalises all other such actions outside that. | LL7: Reveal if mortal/vampire/ghoul; Humanity rating; diablerie | LM7: ¬ | LN7: ¬ | LO7: ¬ | LP7: ¬ | LQ7: ¬ | LR7: ¬ | LS7: ¬ | LT7: ¬ | LU7: ¬ | LV7: ¬ | LW7: ¬ | LX7: ¬ | LY7: ¬ | LZ7: ¬ | MA7: ¬ | MB7: ¬ | MC7: ¬ | MD7: ¬ | ME7: ¬ | MF7: Aloof Curse | MG7: ¬ | MH7: ¬ | MI7: ¬ | MJ7: ¬ | MK7: First Touchstone attaches to Humanity 7; losing it detaches on first Humanity loss. Breaking points always treated as one step lower. | ML7: ¬ | MN7: ¬ | MO7: ¬ | MP7: 5 | MQ7: 9 | MR7: 3 | MS7: Put yourself out to help another succeed. | MT7: Take full responsibility for another's dangerous mistake. | MU7: Convince someone to deny logic because of your word. | MV7: Risk exile or death to defend your cult's belief system. | MW7: ¬ | MX7: ¬ | MY7: ¬ | MZ7: mid 30s
A8: tblCharDataCharlie | B8: 46104 | C8: 0 | D8: 62 | E8: Kurtis W | F8: Charlie Ballsack | G8: Putrescent Invictus secret police | H8: it/it | I8: Nosferatu | J8: D:\Terra Mortis\Character Sheets\Sheet Elements\Nosferatu icon.svg | K8: Order of Sir Martin | L8: Invictus | M8: D:\Terra Mortis\Character Sheets\Sheet Elements\Invictus icon.svg | N8: Conformist | O8: Rebel | P8: ¬ | Q8: ● | R8: ●●● | S8: ●●● | T8: ●●● | U8: ●●● | V8: ●●● | W8: ●● | X8: ●● | Y8: ●●● | AB8: ●●●●† | AH8: ●● | AL8: ●● | AM8: ●●●† | AO8: ●●●●○† | AQ8: ●●† | AS8: ●●† | AU8: ●●● | AX8: ●○○○○○○○○○ | AY8: 1 | BA8: □□□□□□□□■■■■■■■ | BB8: 6 / 6 | BC8: □□□□□□■■■■ | BD8: 10 / 10 | BE8: □□□□□□□□□□■■■■■■■■■■ | BF8: 1 | BG8: Animals | BJ8: Smithing | BU8: Coward Punch | BW8: Lgt Weapons +2, Weapon & Shield +2 | CA8: Interrogation | CF8: 1 | CG8: 2 | CH8: 3 | CI8: Invictus | CJ8: ●●● | CK8: Carthian | CL8: - | CM8: Crone | CN8: - | CO8: Lance | CP8: - | CQ8: ●●● | CR8: ●●● | CS8: - | CT8: ●●●●● | CU8: ●●●●● | CV8: The Ashen Path | CW8: ●●●● | CY8: 4 | CZ8: ˅ | DA8: ○ | DB8: ○ | DC8: ○ | DD8: ○ | DE8: ○ (Priya (saved assailant)) | DF8: ○ | DG8: ● | DH8: ● | DI8: ● | DJ8: ● | DK8: Area of Expertise (Coward Punch) ● | DL8: Area of Expertise (Light Weapons) ● | DM8: Area of Expertise (Weapon & Shield) ● | DN8: Closed Book ●●● | DO8: Defensive Combat (Weaponry) ● | DP8: Friends in High Places ● | DQ8: Indomitable ●● | DR8: Interdisciplinary Specialty (Coward Punch) ● | DS8: Invested ● | DT8: Secret Society Junkie ● | DU8: Courtoisie ● | Establish the Duel | DV8: Courtoisie ●●● | Demanding Attention | DW8: Light Weapons ●● | Thrust | DX8: Light Weapons ●●●● | Flurry | DY8: Strength Performance ● | Strength Tricks | DZ8: Strength Performance ●● | Lifting | EA8: Strength Performance ●●● | Push/Pull | EB8: Strength Performance ●●●● | Stronger Than You | EC8: Weapon and Shield ● | Shield Bash | ED8: Weapon and Shield ●●● | Pin Weapon | EE8: ¬ | EF8: ¬ | EG8: ¬ | EH8: ¬ | EI8: ¬ | EJ8: ¬ | EK8: ¬ | EL8: ¬ | EM8: ¬ | EN8: ¬ | EO8: Raise one Specialty's die bonus to +2. | EP8: Raise one Specialty's die bonus to +2. | EQ8: Raise one Specialty's die bonus to +2. | ER8: Add dots to Doors and as bonus to contest Social assessments. | ES8: Substitute chosen Skill for Athletics in Defence, if equipped for that Skill. | ET8: Once per chapter, use Invictus Status as Mortal Status in areas you don't possess. Drawback: Other Invictus may be informed. | EU8: +2 to contest or resist supernatural mental influence. | EV8: Apply one Specialty's bonus to relevant rolls of any Skill (not unskilled). | EW8: Distribute Invictus Status dots among free Herd, Mentor, Resources and Retainer. | EX8: Dots in Status or Mystery Cult Initiation representing human secret societies also count as dots of Herd. | EY8: Choose an attacker. So long as you don't attack anyone else, add Weaponry as a Defence bonus against outside parties, and deal a point of lethal damage when an outside party enters range. | EZ8: Once you Establish the Duel, if your opponent tries to disengage or attack someone else, you can deal your Socialise dots in lethal damage and leave him Knocked Down. | FA8: Sacrifice points of Defence for bonus attack dice. | FB8: Inflict a point of lethal damage per turn to opponents in range when your Defence is available. | FC8: Take +1 to nonviolent feats of strength, +2 when using Expression or Intimidation. | FD8: Receive the rote quality on Strength + Stamina feats and combat actions to demolish structures. | FE8: Double your effective Strength to shift objects across a plane, or quintuple it with wheels or other friction reductions. | FF8: Successful Strength rolls add an additional free success. | FG8: Add your shield's Size as bonus dice when dodging. Dodge successes in excess of your opponent's inflict bashing damage. | FH8: Disarm assailants on missed melee attacks. | FI8: ¬ | FJ8: ¬ | FK8: ¬ | FL8: ¬ | FM8: ¬ | FN8: ¬ | FO8: ¬ | FP8: ¬ | FQ8: ¬ | FR8: ¬ | FS8: 5 / 5 | FT8: □□□□□ | FU8: Allies | FV8: Contacts | FW8: Resources | FX8: ¬ | FY8: ¬ | FZ8: ¬ | GA8: ¬ | GB8: ¬ | GC8: ¬ | GD8: ¬ | GE8: ¬ | GF8: ¬ | GG8: ¬ | GH8: ¬ | GI8: ¬ | GJ8: ¬ | GK8: ¬ | GL8: ¬ | GM8: ¬ | GN8: ¬ | GO8: Police | GP8: Street, Underworld, Police | GQ8: ¬ | GR8: ¬ | GS8: ¬ | GT8: ¬ | GU8: ¬ | GV8: ¬ | GW8: ¬ | GX8: ¬ | GY8: ¬ | GZ8: ¬ | HA8: ¬ | HB8: ¬ | HC8: ¬ | HD8: ¬ | HE8: ¬ | HF8: ¬ | HG8: ¬ | HH8: ¬ | HI8: ● | HJ8: ●●● | HK8: ●●●●● | IC8: - | ID8: - | IE8: ● | IF8: - | IG8: - | IH8: ● | II8: ●●●●● | IJ8: - | IK8: - | IL8: - | IM8: - | IN8: - | IO8: - | IP8: - | IQ8: - | IR8: - | IS8: - | IT8: Celerity ● | IU8: Nightmare ● | Dread Presence | IV8: Obfuscate ● | Face in the Crowd | IW8: Obfuscate ●● | Touch of Shadow | IX8: Obfuscate ●●● | Cloak of Night | IY8: Obfuscate ●●●● | The Familiar Stranger | IZ8: Obfuscate ●●●●● | Oubliette | JA8: Devotion | Repulsive Mien | JB8: Oath of Fealty ● | JC8: Oath of the Hard Motherfucker ●● | JD8: Oath of the Safe Word ●● | JE8: Oath of the True Knight ●●●● | JF8: ¬ | JG8: ¬ | JH8: ¬ | JI8: ¬ | JJ8: ¬ | JK8: ¬ | JL8: ¬ | JM8: ¬ | JN8: ¬ | JO8: ¬ | JP8: ¬ | JQ8: ¬ | JR8: ¬ | JS8: ¬ | JT8: ¬ | JU8: ¬ | JV8: ¬ | JW8: ¬ | JX8: Cost: 1 V per effect • Pool: - • Reflexive • 1 turn | JY8: Cost: - • Pool: - • Instant • Scene | JZ8: Cost: - • Pool: - • Instant • Scene | KA8: Cost: 1 V • Pool: 10 • Instant • Scene | KB8: Cost: 1 V • Pool: - • None | KC8: Cost: 2 V • Pool: - • None | KD8: Cost: Free (Haven) / 3-9 V & 1 WP • Pool: - • Instant • 1 week per BP | KE8: Cost: 1 V (Order of Sir Martin Only); only affects other Leper Knights with concrete reasons for mistrust • Pool: - • Reflexive • Scene | KF8: ¬ | KG8: ¬ | KH8: ¬ | KI8: ¬ | KJ8: ¬ | KK8: ¬ | KL8: ¬ | KM8: ¬ | KN8: ¬ | KO8: ¬ | KP8: ¬ | KQ8: ¬ | KR8: ¬ | KS8: ¬ | KT8: ¬ | KU8: ¬ | KV8: ¬ | KW8: ¬ | KX8: ¬ | KY8: ¬ | KZ8: ¬ | LA8: ¬ | LB8: Persistent improved Defence or Dodge. Activate for supernatural speed benefits. Unnatural Grace: add Celerity dots as bonus dice to non-combat speed-based pools. | LC8: Conjure brief illusions. Improve Intimidation. Prevent foes spending Willpower. | LD8: Blend into surroundings, visible but unnoticeable. Predatory aura fully on or off. Leaving combat: Wits + Composure - Obfuscate to notice; auto Clash of Wills vs Auspex. | LE8: Cast Face in the Crowd on object or person. Free and unlimited duration on carried/worn objects if not drawing attention. | LF8: Become invisible. Leaving combat: auto Clash of Wills vs Auspex 2. | LG8: Disguise self or other as a desired person. Free unlimited duration to reskin carried/worn objects, but no equipment bonus without Vitae. | LH8: Always active on Haven/Safe Place at no cost. Further uses at standard cost. Use Obfuscate at distance on anything in area. | LI8: As Dread Presence but -3 to all actions against the Knight. Targets cannot spend WP to enhance actions against Knight. Victims can lash out with Beast to end the effect. Reflexive brief illusions affecting Knight's person (narrative only). | LJ8: Draw Invictus Status in Vitae weekly from liege without feeding. Liege knows when you lie. | LK8: Kill a Carthian or oathbreaker for Invictus Status 1, Friends in High Places 1, 9-Again on two Skills, and Allies/Contacts/Resources 1. All stripped if broken. | LL8: Share Willpower and one Social Merit with oath partner. Either can end to briefly paralyse the other. | LM8: Impartial covenant defender. Can't consume Vitae from any source; can't be woken from torpor by blood. Invictus Status protects from mental Disciplines and Kindred/ghoul attacks. | LN8: ¬ | LO8: ¬ | LP8: ¬ | LQ8: ¬ | LR8: ¬ | LS8: ¬ | LT8: ¬ | LU8: ¬ | LV8: ¬ | LW8: ¬ | LX8: ¬ | LY8: ¬ | LZ8: ¬ | MA8: ¬ | MB8: ¬ | MC8: ¬ | MD8: ¬ | ME8: ¬ | MF8: Lonely Curse | MG8: ¬ | MH8: Rat King/Queen | MI8: ¬ | MJ8: ¬ | MK8: With mortals, Humanity counts –2; Presence/Manipulation failures become dramatic failures. Intimidation and Subterfuge unaffected. | ML8: ¬ | MM8: Surrounded by vermin; all Social rolls fail except Intimidation; WP can dismiss. | MN8: ¬ | MO8: ¬ | MP8: 5 | MQ8: 11 | MR8: 5 | MS8: Choose an obviously disadvantageous path because it fits with protocol. | MT8: Stand by the losing side with shield at the ready, because it is your side. | MU8: Openly flout a tradition. | MV8: Openly flout a Kindred Tradition or a covenant taboo. | MW8: ¬ | MX8: ¬ | MY8: ¬ | MZ8: indeterminate
A9: tblCharDataConrad | B9: 46104 | C9: 0 | D9: 40 | E9: Arnold W | F9: Conrad Sondergaard | G9: Occult gentleman detective | H9: he/him | I9: Mekhet | J9: D:\Terra Mortis\Character Sheets\Sheet Elements\Mekhet icon.svg | K9: ¬ | L9: Lancea et Sanctum | M9: D:\Terra Mortis\Character Sheets\Sheet Elements\Lance icon.svg | N9: Follower | O9: Spy | P9: ¬ | Q9: ●●●● | R9: ●●● | S9: ●● | T9: ● | U9: ●●● | V9: ●● | W9: ●● | X9: ●● | Y9: ●●● | Z9: ●●●● | AC9: ●●●† | AE9: ●●●● | AK9: ● | AM9: ●●●† | AQ9: ●●●○† | AW9: ● | AX9: ●●○○○○○○○○ | AY9: 2 | AZ9: † | BA9: □□□□□□□■■■■■■■■ | BB9: 5 / 5 | BC9: □□□□□■■■■■ | BD9: 11 / 11 | BE9: □□□□□□□□□□□■■■■■■■■■ | BF9: 2 | BG9: Animals | BH9: Criminology | BK9: Crime Scene | BS9: Pistols | BU9: Stalking | BY9: Motives | CF9: 2 | CG9: 2 | CH9: 3 | CI9: Lance | CJ9: ●●● | CK9: Carthian | CL9: - | CM9: Crone | CN9: - | CO9: Invictus | CP9: - | CQ9: - | CR9: - | CS9: - | CT9: ● | CU9: - | CW9: ●●●● | CX9: Private Investigator | CY9: 7 | CZ9: ~ | DA9: ○ | DB9: ○ | DC9: ○ | DD9: ● | DE9: ● (Elise (Granddaughter)) | DF9: ● | DG9: ● | DH9: ● | DI9: ● | DJ9: ● | DK9: Acute Senses ● | DL9: ¬ | DM9: ¬ | DN9: ¬ | DO9: ¬ | DP9: ¬ | DQ9: ¬ | DR9: ¬ | DS9: ¬ | DT9: ¬ | DU9: ¬ | DV9: ¬ | DW9: ¬ | DX9: ¬ | DY9: ¬ | DZ9: ¬ | EA9: ¬ | EB9: ¬ | EC9: ¬ | ED9: ¬ | EE9: ¬ | EF9: ¬ | EG9: ¬ | EH9: ¬ | EI9: ¬ | EJ9: ¬ | EK9: ¬ | EL9: ¬ | EM9: ¬ | EN9: ¬ | EO9: Add Blood Potency to sensory rolls. Exceptional success can inflict Obsession. | EP9: ¬ | EQ9: ¬ | ER9: ¬ | ES9: ¬ | ET9: ¬ | EU9: ¬ | EV9: ¬ | EW9: ¬ | EX9: ¬ | EY9: ¬ | EZ9: ¬ | FA9: ¬ | FB9: ¬ | FC9: ¬ | FD9: ¬ | FE9: ¬ | FF9: ¬ | FG9: ¬ | FH9: ¬ | FI9: ¬ | FJ9: ¬ | FK9: ¬ | FL9: ¬ | FM9: ¬ | FN9: ¬ | FO9: ¬ | FP9: ¬ | FQ9: ¬ | FR9: ¬ | FS9: 5 / 5 | FT9: □□□□□ | FU9: Contacts | FV9: ¬ | FW9: ¬ | FX9: ¬ | FY9: ¬ | FZ9: ¬ | GA9: ¬ | GB9: ¬ | GC9: ¬ | GD9: ¬ | GE9: ¬ | GF9: ¬ | GG9: ¬ | GH9: ¬ | GI9: ¬ | GJ9: ¬ | GK9: ¬ | GL9: ¬ | GM9: ¬ | GN9: ¬ | GO9: Police, Underworld | GP9: ¬ | GQ9: ¬ | GR9: ¬ | GS9: ¬ | GT9: ¬ | GU9: ¬ | GV9: ¬ | GW9: ¬ | GX9: ¬ | GY9: ¬ | GZ9: ¬ | HA9: ¬ | HB9: ¬ | HC9: ¬ | HD9: ¬ | HE9: ¬ | HF9: ¬ | HG9: ¬ | HH9: ¬ | HI9: ●● | IC9: - | ID9: ●●●●● | IE9: - | IF9: - | IG9: - | IH9: - | II9: ● | IJ9: - | IK9: - | IL9: - | IM9: - | IN9: ●●●● | IO9: - | IP9: - | IQ9: ● | IR9: ●●●● | IS9: ● | IT9: Auspex ● | Beast's Hackles | IU9: Auspex ●● | Uncanny Perception | IV9: Auspex ●●● | Spirit's Touch | IW9: Auspex ●●●● | Lay Open the Mind | IX9: Auspex ●●●●● | Twilight Projection | IY9: Obfuscate ● | Face in the Crowd | IZ9: Blood Sorcery | Divination ● | JA9: Blood Sorcery | Protection ● | JB9: Blood Sorcery | Protection ●● | JC9: Blood Sorcery | Protection ●●● | JD9: Blood Sorcery | Protection ●●●● | JE9: Blood Sorcery | Transmutation ● | JF9: ¬ | JG9: ¬ | JH9: ¬ | JI9: ¬ | JJ9: ¬ | JK9: ¬ | JL9: ¬ | JM9: ¬ | JN9: ¬ | JO9: ¬ | JP9: ¬ | JQ9: ¬ | JR9: ¬ | JS9: ¬ | JT9: ¬ | JU9: ¬ | JV9: ¬ | JW9: ¬ | JX9: Cost: Free (1 V for Insight) • Pool: - - Composure & Closed Book • Instant • Scene | JY9: Cost: Free (1 V for Insight) Must perceive target • Pool: - • Instant • Scene | JZ9: Cost: Free (1 WP for clash / 1 V for Insight) • Pool: - v Resolve + Stealth + Obf • Reflexive • Immediate | KA9: Cost: 1 V • Pool: 8 v Resolve + BP • Instant • Scene | KB9: Cost: 2 V • Pool: 13 • Instant • Scene (while projected) | KC9: Cost: - • Pool: - • Instant • Scene | KD9: ¬ | KE9: ¬ | KF9: ¬ | KG9: ¬ | KH9: ¬ | KI9: ¬ | KJ9: ¬ | KK9: ¬ | KL9: ¬ | KM9: ¬ | KN9: ¬ | KO9: ¬ | KP9: ¬ | KQ9: ¬ | KR9: ¬ | KS9: ¬ | KT9: ¬ | KU9: ¬ | KV9: ¬ | KW9: ¬ | KX9: ¬ | KY9: ¬ | KZ9: ¬ | LA9: ¬ | LB9: Add Auspex dots to any rolls to resist surprise. Access to Tier 1 Auspex Insight questions. | LC9: Persistent Acute Senses Merit, doubles actual merit. Access to Tier 2 Auspex Insight questions. | LD9: Passively scan for anyone under Obfuscate 1 or 3, can provoke a challenge. Access to Tier 3 Auspex Insight questions. | LE9: Telepathy and mind-reading. Invoke Conditions. | LF9: Project senses into Twilight. May use Auspex 1-3 once per scene; cannot spend blood for additional uses. | LG9: Blend into surroundings, visible but unnoticeable. Predatory aura fully on or off. Leaving combat: Wits + Composure - Obfuscate to notice; auto Clash of Wills vs Auspex. | LH9: Glimpse fragmented details about intended actions. Learn basic info about a target. | LI9: Subtract Potency from ritual rolls targeting subject. Heal bashing in vampires. Protect from the Kiss (add Potency to resistance). | LJ9: Grant armour. Ward environmental hazards. Resist frenzy. | LK9: Render untouchable or unable to be fed from. Ward physical Discipline effects. Protect from staking. Heal lethal in vampires. | LL9: Ward mental Discipline effects (Majesty, Dominate). Protect from Vinculum. Remain active during day (Potency turns). | LM9: Minor cosmetic changes to living subjects. Warp dead matter. Animate liquids. | LN9: ¬ | LO9: ¬ | LP9: ¬ | LQ9: ¬ | LR9: ¬ | LS9: ¬ | LT9: ¬ | LU9: ¬ | LV9: ¬ | LW9: ¬ | LX9: ¬ | LY9: ¬ | LZ9: ¬ | MA9: ¬ | MB9: ¬ | MC9: ¬ | MD9: ¬ | ME9: ¬ | MF9: Tenebrous Curse | MG9: ¬ | MH9: ¬ | MI9: ¬ | MJ9: ¬ | MK9: Gain an extra bane at Humanity 6 (doesn't count towards cap); Humanity counts –1 for all Humanity-based banes. | ML9: ¬ | MN9: ¬ | MO9: ¬ | MP9: 5 | MQ9: 9 | MR9: 3 | MS9: Follow a directive blindly, for the sake of following. | MT9: Follow a dangerous directive without hesitation. | MU9: Build a new identity or uncover a secret. | MV9: Uncover a damning secret that could end someone. | MW9: ¬ | MX9: ¬ | MY9: ¬ | MZ9: late 20s
